<?xml version="1.0"?>
<robot name="GBT_C5A_wrist_camera_gripper">

  <!-- ==================== Base Robot ==================== -->
  <!-- Base Link: base_link -->
  <link name="base_link">
    <inertial>
      <origin xyz="-5.18937271871501E-06 -0.00981292786589054 0.0491107475197807" rpy="0 0 0" />
      <mass value="9.16039502558691" />
      <inertia ixx="0.0419459273106292" ixy="1.03238231774288E-05" ixz="-1.20730153954149E-06" iyy="0.0160794902925854" iyz="-0.00415210475211165" izz="0.0465551463891972" />
    </inertial>
    <visual>
      <origin xyz="0 0 0" rpy="0 0 0"/>
      <geometry>
        <mesh filename="../meshes/visual/base_link.obj" scale="0.001 0.001 0.001"/>
      </geometry>
    </visual>
    <collision>
      <origin xyz="0 0 0" rpy="0 0 0"/>
      <geometry>
        <mesh filename="../meshes/collision/base_link.stl" scale="0.001 0.001 0.001"/>
      </geometry>
    </collision>
  </link>

  <!-- link1 -->
  <joint name="joint1" type="revolute">
    <parent link="base_link"/>
    <child link="link1"/>
    <origin xyz="0 0 0.178" rpy="0 0 0"/>
    <axis xyz="0 0 1"/>
    <limit effort="100" lower="-6.283185307179" upper="6.283185307179" velocity="1"/>
  </joint>
  <link name="link1">
    <inertial>
      <origin xyz="-4.1533E-07 0.0039849 0.082573" rpy="0 0 0" />
      <mass value="15.175" />
      <inertia ixx="0.047238" ixy="1.1824E-07" ixz="3.158E-07" iyy="0.045941" iyz="-9.9968E-05" izz="0.029087" />
    </inertial>
    <visual>
      <origin xyz="0 0 0" rpy="0 0 0"/>
      <geometry>
        <mesh filename="../meshes/visual/link1.obj" scale="0.001 0.001 0.001"/>
      </geometry>
    </visual>
    <collision>
      <origin xyz="0 0 0" rpy="0 0 0"/>
      <geometry>
        <mesh filename="../meshes/collision/link1.stl" scale="0.001 0.001 0.001"/>
      </geometry>
    </collision>
  </link>

  <!-- link2 -->
  <joint name="joint2" type="revolute">
    <parent link="link1"/>
    <child link="link2"/>
    <origin xyz="0 0.147 0" rpy="1.5707963267948966 0 0"/>
    <axis xyz="0 0 1"/>
    <limit effort="100" lower="-1.483529864195" upper="4.625122517784" velocity="1"/>
  </joint>
  <link name="link2">
    <inertial>
      <origin xyz="0.21249 -1.5735E-06 0.083052" rpy="0 0 0" />
      <mass value="45.747" />
      <inertia ixx="0.10914" ixy="4.6633E-05" ixz="2.2941E-06" iyy="1.56" iyz="3.3978E-06" izz="1.5237" />
    </inertial>
    <visual>
      <origin xyz="0 0 0" rpy="0 0 0"/>
      <geometry>
        <mesh filename="../meshes/visual/link2.obj" scale="0.001 0.001 0.001"/>
      </geometry>
    </visual>
    <collision>
      <origin xyz="0 0 0" rpy="0 0 0"/>
      <geometry>
        <mesh filename="../meshes/collision/link2.stl" scale="0.001 0.001 0.001"/>
      </geometry>
    </collision>
  </link>

  <!-- link3 -->
  <joint name="joint3" type="revolute">
    <parent link="link2"/>
    <child link="link3"/>
    <origin xyz="0.425 0 0.072" rpy="0 0 0"/>
    <axis xyz="0 0 1"/>
    <limit effort="100" lower="-2.879793265790" upper="2.879793265790" velocity="1"/>
  </joint>
  <link name="link3">
    <inertial>
      <origin xyz="-0.17704 2.1965E-06 0.057289" rpy="0 0 0" />
      <mass value="25.388" />
      <inertia ixx="0.034609" ixy="2.0726E-06" ixz="0.017944" iyy="0.57881" iyz="-1.6149E-06" izz="0.57165" />
    </inertial>
    <visual>
      <origin xyz="0 0 0" rpy="0 0 0"/>
      <geometry>
        <mesh filename="../meshes/visual/link3.obj" scale="0.001 0.001 0.001"/>
      </geometry>
    </visual>
    <collision>
      <origin xyz="0 0 0" rpy="0 0 0"/>
      <geometry>
        <mesh filename="../meshes/collision/link3.stl" scale="0.001 0.001 0.001"/>
      </geometry>
    </collision>
  </link>

  <!-- link4 -->
  <joint name="joint4" type="revolute">
    <parent link="link3"/>
    <child link="link4"/>
    <origin xyz="0.385 0 -0.052" rpy="0 0 0"/>
    <axis xyz="0 0 1"/>
    <limit effort="100" lower="-1.483529864195" upper="4.625122517784" velocity="1"/>
  </joint>
  <link name="link4">
    <inertial>
      <origin xyz="1.4636E-07 0.0036936 0.046819" rpy="0 0 0" />
      <mass value="5.9625" />
      <inertia ixx="0.01117" ixy="6.5877E-08" ixz="-9.2842E-08" iyy="0.0057359" iyz="-0.00011921" izz="0.010395" />
    </inertial>
    <visual>
      <origin xyz="0 0 0" rpy="0 0 0"/>
      <geometry>
        <mesh filename="../meshes/visual/link4.obj" scale="0.001 0.001 0.001"/>
      </geometry>
    </visual>
    <collision>
      <origin xyz="0 0 0" rpy="0 0 0"/>
      <geometry>
        <mesh filename="../meshes/collision/link4.stl" scale="0.001 0.001 0.001"/>
      </geometry>
    </collision>
  </link>

  <!-- link5 -->
  <joint name="joint5" type="revolute">
    <parent link="link4"/>
    <child link="link5"/>
    <origin xyz="0 -0.1233 0" rpy="1.5707963267948966 0 0"/>
    <axis xyz="0 0 1"/>
    <limit effort="100" lower="-6.283185307179" upper="6.283185307179" velocity="1"/>
  </joint>
  <link name="link5">
    <inertial>
      <origin xyz="2.8003E-07 -0.00083604 -0.04715" rpy="0 0 0" />
      <mass value="6.3692" />
      <inertia ixx="0.013244" ixy="1.2468E-07" ixz="-2.2495E-08" iyy="0.0060649" iyz="-1.9528E-05" izz="0.012458" />
    </inertial>
    <visual>
      <origin xyz="0 0 0" rpy="0 0 0"/>
      <geometry>
        <mesh filename="../meshes/visual/link5.obj" scale="0.001 0.001 0.001"/>
      </geometry>
    </visual>
    <collision>
      <origin xyz="0 0 0" rpy="0 0 0"/>
      <geometry>
        <mesh filename="../meshes/collision/link5.stl" scale="0.001 0.001 0.001"/>
      </geometry>
    </collision>
  </link>

  <!-- link6 -->
  <joint name="joint6" type="revolute">
    <parent link="link5"/>
    <child link="link6"/>
    <origin xyz="0 -0.1003 0" rpy="1.5707963267948966 0 0"/>
    <axis xyz="0 0 1"/>
    <limit effort="100" lower="-6.283185307179" upper="6.283185307179" velocity="1"/>
  </joint>
  <link name="link6">
    <inertial>
      <origin xyz="1.3558E-09 0.00017433 0.012497" rpy="0 0 0" />
      <mass value="1.0139" />
      <inertia ixx="0.00046196" ixy="1.0902E-10" ixz="2.167E-10" iyy="0.00046763" iyz="-6.5718E-08" izz="0.00080289" />
    </inertial>
    <visual>
      <origin xyz="0 0 0" rpy="0 0 0"/>
      <geometry>
        <mesh filename="../meshes/visual/link6.obj" scale="0.001 0.001 0.001"/>
      </geometry>
    </visual>
    <collision>
      <origin xyz="0 0 0" rpy="0 0 0"/>
      <geometry>
        <mesh filename="../meshes/collision/link6.stl" scale="0.001 0.001 0.001"/>
      </geometry>
    </collision>
  </link>

  <!-- ==================== Camera Mount ==================== -->
  <!-- Camera Mount Link -->
  <link name="camera_mount_link">
    <inertial>
      <origin xyz="0 0 0.003" rpy="0 0 0" />
      <mass value="0.16" />
      <inertia ixx="0.0001" ixy="0" ixz="0" iyy="0.0001" iyz="0" izz="0.0001" />
    </inertial>
    <visual>
      <origin xyz="0 0 0" rpy="-1.57079632679 0 0"/>
      <geometry>
        <mesh filename="../meshes/visual/camera_mount.obj" scale="0.1 0.1 0.1"/>
      </geometry>
    </visual>
    <collision>
      <origin xyz="0 0 0." rpy="-1.57079632679 0 0"/>
      <geometry>
        <mesh filename="../meshes/collision/camera_mount.stl" scale="0.1 0.1 0.1"/>
      </geometry>
    </collision>
  </link>

  <!-- Camera pose frame on the camera mount -->
  <link name="camera_link"/>

  <!-- Joint: link6 -> camera_mount_link -->
  <joint name="camera_mount_joint" type="fixed">
    <parent link="link6"/>
    <child link="camera_mount_link"/>
    <origin xyz="0 0 0.012" rpy="1.57079632679 0 3.1415926535"/>
  </joint>

  <!-- Joint: camera mount -> camera pose frame -->
  <joint name="camera_link_joint" type="fixed">
    <parent link="camera_mount_link"/>
    <child link="camera_link"/>
    <origin xyz="0 0.01325 -0.06997" rpy="-1.2217304763960306 0 0"/>
  </joint>

  <!-- ==================== Robotiq 2F-140 Gripper ==================== -->
  <!-- Gripper mounts on top of the camera mount -->
  <joint name="gripper_joint" type="fixed">
    <parent link="camera_mount_link"/>
    <child link="robotiq_arg2f_base_link"/>
    <origin xyz="0  0.012 0" rpy="-1.57079632679 -1.57079632679 0"/>
  </joint>

  <!-- Robotiq 2F-140 Gripper Links -->
  <link name="robotiq_arg2f_base_link">
    <inertial>
      <origin xyz="8.625E-08 -4.6583E-06 0.03145" rpy="0 0 0" />
      <mass value="0.22652" />
      <inertia ixx="0.00020005" ixy="-4.2442E-10" ixz="-2.9069E-10" iyy="0.00017832" iyz="-3.4402E-08" izz="0.00013478" />
    </inertial>
    <visual>
      <origin xyz="0 0 0" rpy="0 0 0" />
      <geometry>
        <mesh filename="../meshes/visual/robotiq_arg2f_base_link.stl" />
      </geometry>
      <material name="">
        <color rgba="0.1 0.1 0.1 1" />
      </material>
    </visual>
    <collision>
      <origin xyz="0 0 0" rpy="0 0 0" />
      <geometry>
        <mesh filename="../meshes/collision/robotiq_arg2f_base_link.stl" />
      </geometry>
    </collision>
  </link>

  <!-- Left Finger Assembly -->
  <link name="left_outer_knuckle">
    <inertial>
      <origin xyz="-0.000200000000003065 0.0199435877845359 0.0292245259211331" rpy="0 0 0" />
      <mass value="0.00853198276973456" />
      <inertia ixx="2.89328108496468E-06" ixy="-1.57935047237397E-19" ixz="-1.93980378593255E-19" iyy="1.86719750325683E-06" iyz="-1.21858577871576E-06" izz="1.21905238907251E-06" />
    </inertial>
    <visual>
      <origin xyz="0 0 0" rpy="0 0 0" />
      <geometry>
        <mesh filename="../meshes/visual/robotiq_arg2f_140_outer_knuckle.stl" />
      </geometry>
      <material name="">
        <color rgba="0.792156862745098 0.819607843137255 0.933333333333333 1" />
      </material>
    </visual>
    <collision>
      <origin xyz="0 0 0" rpy="0 0 0" />
      <geometry>
        <mesh filename="../meshes/collision/robotiq_arg2f_140_outer_knuckle.stl" />
      </geometry>
    </collision>
  </link>

  <link name="left_outer_finger">
    <inertial>
      <origin xyz="0.00030115855001899 0.0373907951953854 -0.0208027427000385" rpy="0 0 0" />
      <mass value="0.022614240507152" />
      <inertia ixx="1.52518312458174E-05" ixy="9.76583423954399E-10" ixz="-5.43838577022588E-10" iyy="6.17694243867776E-06" iyz="6.78636130740228E-06" izz="1.16494917907219E-05" />
    </inertial>
    <visual>
      <origin xyz="0 0 0" rpy="0 0 0" />
      <geometry>
        <mesh filename="../meshes/visual/robotiq_arg2f_140_outer_finger.stl" />
      </geometry>
      <material name="">
        <color rgba="0.1 0.1 0.1 1" />
      </material>
    </visual>
    <collision>
      <origin xyz="0 0 0" rpy="0 0 0" />
      <geometry>
        <mesh filename="../meshes/collision/robotiq_arg2f_140_outer_finger.stl" />
      </geometry>
    </collision>
  </link>

  <link name="left_inner_finger">
    <inertial>
      <origin xyz="0.000299999999999317 0.0160078233491243 -0.0136945669206257" rpy="0 0 0" />
      <mass value="0.0104003125914103" />
      <inertia ixx="2.71909453810972E-06" ixy="1.35402465472579E-21" ixz="-7.1817349065269E-22" iyy="7.69100314106116E-07" iyz="6.74715432769696E-07" izz="2.30315190420171E-06" />
    </inertial>
    <visual>
      <origin xyz="0 0 0" rpy="0 0 0" />
      <geometry>
        <mesh filename="../meshes/visual/robotiq_arg2f_140_inner_finger.stl" />
      </geometry>
      <material name="">
        <color rgba="0.1 0.1 0.1 1" />
      </material>
    </visual>
    <collision>
      <origin xyz="0 0 0" rpy="0 0 0" />
      <geometry>
        <mesh filename="../meshes/collision/robotiq_arg2f_140_inner_finger.stl" />
      </geometry>
    </collision>
  </link>

  <link name="left_inner_finger_pad">
    <visual>
      <origin xyz="0 0 0" rpy="0 0 0" />
      <geometry>
        <box size="0.027 0.065 0.0075" />
      </geometry>
      <material name="">
        <color rgba="0.9 0.9 0.9 1" />
      </material>
    </visual>
    <collision>
      <origin xyz="0 0 0" rpy="0 0 0" />
      <geometry>
        <box size="0.03 0.07 0.0075" />
      </geometry>
      <material name="">
        <color rgba="0.9 0.0 0.0 1" />
      </material>
    </collision>
  </link>

  <link name="left_inner_knuckle">
    <inertial>
      <origin xyz="0.000123011831763771 0.0507850843201817 0.00103968640075166" rpy="0 0 0" />
      <mass value="0.0271177346495152" />
      <inertia ixx="2.61910379223783E-05" ixy="-2.43616858946494E-07" ixz="-6.37789906117123E-09" iyy="2.8270243746167E-06" iyz="-5.37200748039765E-07" izz="2.83695868220296E-05" />
    </inertial>
    <visual>
      <origin xyz="0 0 0" rpy="0 0 0" />
      <geometry>
        <mesh filename="../meshes/visual/robotiq_arg2f_140_inner_knuckle.stl" />
      </geometry>
      <material name="">
        <color rgba="0.1 0.1 0.1 1" />
      </material>
    </visual>
    <collision>
      <origin xyz="0 0 0" rpy="0 0 0" />
      <geometry>
        <mesh filename="../meshes/collision/robotiq_arg2f_140_inner_knuckle.stl" />
      </geometry>
    </collision>
  </link>

  <!-- Right Finger Assembly -->
  <link name="right_outer_knuckle">
    <inertial>
      <origin xyz="-0.000200000000003065 0.0199435877845359 0.0292245259211331" rpy="0 0 0" />
      <mass value="0.00853198276973456" />
      <inertia ixx="2.89328108496468E-06" ixy="-1.57935047237397E-19" ixz="-1.93980378593255E-19" iyy="1.86719750325683E-06" iyz="-1.21858577871576E-06" izz="1.21905238907251E-06" />
    </inertial>
    <visual>
      <origin xyz="0 0 0" rpy="0 0 0" />
      <geometry>
        <mesh filename="../meshes/visual/robotiq_arg2f_140_outer_knuckle.stl" />
      </geometry>
      <material name="">
        <color rgba="0.792156862745098 0.819607843137255 0.933333333333333 1" />
      </material>
    </visual>
    <collision>
      <origin xyz="0 0 0" rpy="0 0 0" />
      <geometry>
        <mesh filename="../meshes/collision/robotiq_arg2f_140_outer_knuckle.stl" />
      </geometry>
    </collision>
  </link>

  <link name="right_outer_finger">
    <inertial>
      <origin xyz="0.00030115855001899 0.0373907951953854 -0.0208027427000385" rpy="0 0 0" />
      <mass value="0.022614240507152" />
      <inertia ixx="1.52518312458174E-05" ixy="9.76583423954399E-10" ixz="-5.43838577022588E-10" iyy="6.17694243867776E-06" iyz="6.78636130740228E-06" izz="1.16494917907219E-05" />
    </inertial>
    <visual>
      <origin xyz="0 0 0" rpy="0 0 0" />
      <geometry>
        <mesh filename="../meshes/visual/robotiq_arg2f_140_outer_finger.stl" />
      </geometry>
      <material name="">
        <color rgba="0.1 0.1 0.1 1" />
      </material>
    </visual>
    <collision>
      <origin xyz="0 0 0" rpy="0 0 0" />
      <geometry>
        <mesh filename="../meshes/collision/robotiq_arg2f_140_outer_finger.stl" />
      </geometry>
    </collision>
  </link>

  <link name="right_inner_finger">
    <inertial>
      <origin xyz="0.000299999999999317 0.0160078233491243 -0.0136945669206257" rpy="0 0 0" />
      <mass value="0.0104003125914103" />
      <inertia ixx="2.71909453810972E-06" ixy="1.35402465472579E-21" ixz="-7.1817349065269E-22" iyy="7.69100314106116E-07" iyz="6.74715432769696E-07" izz="2.30315190420171E-06" />
    </inertial>
    <visual>
      <origin xyz="0 0 0" rpy="0 0 0" />
      <geometry>
        <mesh filename="../meshes/visual/robotiq_arg2f_140_inner_finger.stl" />
      </geometry>
      <material name="">
        <color rgba="0.1 0.1 0.1 1" />
      </material>
    </visual>
    <collision>
      <origin xyz="0 0 0" rpy="0 0 0" />
      <geometry>
        <mesh filename="../meshes/collision/robotiq_arg2f_140_inner_finger.stl" />
      </geometry>
    </collision>
  </link>

  <link name="right_inner_finger_pad">
    <visual>
      <origin xyz="0 0 0" rpy="0 0 0" />
      <geometry>
        <box size="0.027 0.065 0.0075" />
      </geometry>
      <material name="">
        <color rgba="0.9 0.9 0.9 1" />
      </material>
    </visual>
    <collision>
      <origin xyz="0 0 0" rpy="0 0 0" />
      <geometry>
        <box size="0.03 0.07 0.0075" />
      </geometry>
      <material name="">
        <color rgba="0.9 0.0 0.0 1" />
      </material>
    </collision>
  </link>

  <link name="right_inner_knuckle">
    <inertial>
      <origin xyz="0.000123011831763771 0.0507850843201817 0.00103968640075166" rpy="0 0 0" />
      <mass value="0.0271177346495152" />
      <inertia ixx="2.61910379223783E-05" ixy="-2.43616858946494E-07" ixz="-6.37789906117123E-09" iyy="2.8270243746167E-06" iyz="-5.37200748039765E-07" izz="2.83695868220296E-05" />
    </inertial>
    <visual>
      <origin xyz="0 0 0" rpy="0 0 0" />
      <geometry>
        <mesh filename="../meshes/visual/robotiq_arg2f_140_inner_knuckle.stl" />
      </geometry>
      <material name="">
        <color rgba="0.1 0.1 0.1 1" />
      </material>
    </visual>
    <collision>
      <origin xyz="0 0 0" rpy="0 0 0" />
      <geometry>
        <mesh filename="../meshes/collision/robotiq_arg2f_140_inner_knuckle.stl" />
      </geometry>
    </collision>
  </link>

  <!-- Gripper Joints -->
  <joint name="finger_joint" type="revolute">
    <origin xyz="0 -0.030601 0.054905" rpy="2.2957963267948966 0 0" />
    <parent link="robotiq_arg2f_base_link" />
    <child link="left_outer_knuckle" />
    <axis xyz="-1 0 0" />
    <limit effort="1000" lower="0" upper="0.7" velocity="2.0" />
  </joint>

  <joint name="left_outer_finger_joint" type="fixed">
    <origin xyz="0 0.01821998610742 0.0260018192872234" rpy="0 0 0" />
    <parent link="left_outer_knuckle" />
    <child link="left_outer_finger" />
    <axis xyz="1 0 0" />
  </joint>

  <joint name="left_inner_knuckle_joint" type="revolute">
    <origin xyz="0 -0.0127 0.06142" rpy="2.2957963267948966 0 0" />
    <parent link="robotiq_arg2f_base_link" />
    <child link="left_inner_knuckle" />
    <axis xyz="1 0 0" />
    <limit effort="1000" lower="-0.8757" upper="0.8757" velocity="2.0" />
    <mimic joint="finger_joint" multiplier="-1" offset="0" />
  </joint>

  <joint name="left_inner_finger_joint" type="revolute">
    <origin xyz="0 0.0817554015893473 -0.0282203446692936" rpy="-0.725 0 0" />
    <parent link="left_outer_finger" />
    <child link="left_inner_finger" />
    <axis xyz="1 0 0" />
    <limit effort="1000" lower="-0.8757" upper="0.8757" velocity="2.0" />
    <mimic joint="finger_joint" multiplier="1" offset="0" />
  </joint>

  <joint name="left_inner_finger_pad_joint" type="fixed">
    <origin xyz="0 0.0457554015893473 -0.0272203446692936" rpy="0 0 0" />
    <parent link="left_inner_finger" />
    <child link="left_inner_finger_pad" />
    <axis xyz="0 0 1" />
  </joint>

  <joint name="right_outer_knuckle_joint" type="revolute">
    <origin xyz="0 0.030601 0.054905" rpy="2.2957963267948966 0 3.141592653589793" />
    <parent link="robotiq_arg2f_base_link" />
    <child link="right_outer_knuckle" />
    <axis xyz="1 0 0" />
    <limit effort="1000" lower="-0.725" upper="0.725" velocity="2.0" />
    <mimic joint="finger_joint" multiplier="-1" offset="0" />
  </joint>

  <joint name="right_outer_finger_joint" type="fixed">
    <origin xyz="0 0.01821998610742 0.0260018192872234" rpy="0 0 0" />
    <parent link="right_outer_knuckle" />
    <child link="right_outer_finger" />
    <axis xyz="1 0 0" />
  </joint>

  <joint name="right_inner_knuckle_joint" type="revolute">
    <origin xyz="0 0.0127 0.06142" rpy="2.2957963267948966 0 -3.141592653589793" />
    <parent link="robotiq_arg2f_base_link" />
    <child link="right_inner_knuckle" />
    <axis xyz="1 0 0" />
    <limit effort="1000" lower="-0.8757" upper="0.8757" velocity="2.0" />
    <mimic joint="finger_joint" multiplier="-1" offset="0" />
  </joint>

  <joint name="right_inner_finger_joint" type="revolute">
    <origin xyz="0 0.0817554015893473 -0.0282203446692936" rpy="-0.725 0 0" />
    <parent link="right_outer_finger" />
    <child link="right_inner_finger" />
    <axis xyz="1 0 0" />
    <limit effort="1000" lower="-0.8757" upper="0.8757" velocity="2.0" />
    <mimic joint="finger_joint" multiplier="1" offset="0" />
  </joint>

  <joint name="right_inner_finger_pad_joint" type="fixed">
    <origin xyz="0 0.0457554015893473 -0.0272203446692936" rpy="0 0 0" />
    <parent link="right_inner_finger" />
    <child link="right_inner_finger_pad" />
    <axis xyz="0 0 1" />
  </joint>

  <!-- Transmission for gripper -->
  <transmission name="finger_joint_trans">
    <type>transmission_interface/SimpleTransmission</type>
    <joint name="finger_joint">
      <hardwareInterface>PositionJointInterface</hardwareInterface>
    </joint>
    <actuator name="finger_joint_motor">
      <mechanicalReduction>1</mechanicalReduction>
    </actuator>
  </transmission>

  <!-- ==================== Tool Center Point ==================== -->
  <link name="tcp" />

  <joint name="tcp_joint" type="fixed">
    <parent link="robotiq_arg2f_base_link" />
    <child link="tcp" />
    <!-- Official Robotiq 2F-140 TCP: Z = 244mm from base mount -->
    <origin xyz="0 0 0.234" rpy="0 0 0" />
  </joint>

</robot>
